Workbook

Sheet China Proforma Invoice - New
A4: Proforma Invoice 发票信息表 | I4: 列1
A5: Bill To: 付款方： | D5: Proforma Invoice Number: 形式发票编码： | I5: CNY 人民币 | K5: 增值税专用发票
A6: Contact Person: 付款方联系人： | C6: Alice Niu牛惠香 | D6: Invoice Date: 发票日期： | I6: EUR 欧元 | K6: 增值税普通发票
A7: Department: 付款方联系人所在部门： | C7: KT China | D7: Payment Due Date: 付款日： | I7: GBP 英镑 | K7: 增值税电子专用发票
A8: Kering Internal Contact: 付款方联系人邮箱： | C8: alice.niu@kering.com | D8: Currency: 币种： | F8: CNY 人民币 | I8: HKD 港币 | K8: 增值税电子普通发票
A9: Telephone: 付款方联系人电话： | C9: 15393492085 | D9: Total Amount: 总金额： | H9: =IF(F9=G57,TRUE,FALSE) | I9: USD 美元 | K9: 全电发票
A10: Contract Number: 合同编号： | C10: 非必填项 | D10: Kering Group PO Number: 开云集团内部采购订单号： | I10: TWD 新台币 | K10: 其他
A11: WBS Element: 开云集团内部WBS代码： | C11: 非必填项 | D11: Internal Order: 开云集团内部项目编号： | I11: MYR 马来西亚林吉特 | K11: 预付款，发票后开
A12: WBS Element description: 开云集团内部WBS描述： | C12: =_xlfn.XLOOKUP($C$11,WBS!$G:$G,WBS!$H:$H) | D12: Internal Order description: 开云集团内部项目描述： | F12: =_xlfn.XLOOKUP($F$11,'Internal Order'!$A:$A,'Internal Order'!$B:$B) | I12: SGD 新加坡元
I13: MOP 澳门币
A14: Vendor General Info: 供应商基本信息： | D14: Vendor Bank Info: 供应商收款账户信息: | I14: JPY 日元
A15: SAP Vendor Code: 开云集团付款系统之供应商代码： | C15: 非必填项 | D15: Bank Account Holder Name： 银行开户户名: | F15: 上海珩际信息科技有限公司 | I15: KRW 韩币
A16: Vendor Company Name: 供应商公司名： | C16: 上海珩际信息科技有限公司 | D16: Beneficiary Bank Name: 银行名称: | F16: 中国光大银行上海昌里支行 | I16: AUD 澳元
A17: Company Tax ID： 税号/统一社会信用代码: | C17: 91310114080030903E | D17: Bank Account Number: 银行账号: | F17: 36750188000046804 | I17: CHF 瑞士法郎
A18: Contact Person: 供应商联系人： | C18: Jimmy Wang | D18: IBAN： 国际银行账号： | F18: 仅适用于境外供应商 | I18: SEK 瑞典克朗
A19: Email Address: 供应商联系人邮箱： | C19: jimmy.wang@hengji-info.com | D19: Swift Code: 银行国际代码: | F19: 仅适用于境外供应商 | I19: CAD 加拿大元
A20: Telephone: 供应商联系人电话： | C20: 13818236637 | D20: Bank Address： 银行地址: | F20: 仅适用于境外供应商 | I20: THB 泰铢
I21: VND 越南盾
A22: Project Code: 项目/服务编号： | D22: Invoice Type： 发票类型： | F22: 全电发票 | I22: PHP 菲律宾比索
A23: Project Name: 项目/服务名称和描述： | D23: Remarks： 备注： | I23: INR 印度卢比
A24: Item 序号 | B24: Description 产品/服务描述 | D24: SAP Cost Center 成本中心 | E24: Unit Price 不含税单价 | F24: Quantity 数量 | G24: Total Price 不含税总价 | I24: IDR 印尼盾 | M24: Line Description Details 费用项目明细 | O24: SAP Cost Center Description 成本中心描述
A25: 1 | I25: AED 阿联酋迪拉姆 | L25: =IF(LEN($D25)=9,IF(OR(LEFT($D25,4)="111-",LEFT($D25,4)="119-"),"OK","NO"),"NA") | M25: =IF(B25="","",IF(L25="",B25,#REF!&"-"&B25)) | O25: =_xlfn.XLOOKUP($D25,'Cost Center'!$A:$A,'Cost Center'!$B:$B)
A26: 2 | I26: SAR 沙亚币 | L26: =IF(LEN($D26)=9,IF(OR(LEFT($D26,4)="111-",LEFT($D26,4)="119-"),"OK","NO"),"NA") | M26: =IF(B26="","",IF(L26="",B26,#REF!&"-"&B26)) | O26: =_xlfn.XLOOKUP($D26,'Cost Center'!$A:$A,'Cost Center'!$B:$B)
A27: 3 | L27: =IF(LEN($D27)=9,IF(OR(LEFT($D27,4)="111-",LEFT($D27,4)="119-"),"OK","NO"),"NA") | M27: =IF(B27="","",IF(L27="",B27,#REF!&"-"&B27)) | O27: =_xlfn.XLOOKUP($D27,'Cost Center'!$A:$A,'Cost Center'!$B:$B)
A28: 4 | L28: =IF(LEN($D28)=9,IF(OR(LEFT($D28,4)="111-",LEFT($D28,4)="119-"),"OK","NO"),"NA") | M28: =IF(B28="","",IF(L28="",B28,#REF!&"-"&B28)) | O28: =_xlfn.XLOOKUP($D28,'Cost Center'!$A:$A,'Cost Center'!$B:$B)
A29: 5 | L29: =IF(LEN($D29)=9,IF(OR(LEFT($D29,4)="111-",LEFT($D29,4)="119-"),"OK","NO"),"NA") | M29: =IF(B29="","",IF(L29="",B29,#REF!&"-"&B29)) | O29: =_xlfn.XLOOKUP($D29,'Cost Center'!$A:$A,'Cost Center'!$B:$B)
A30: 6 | L30: =IF(LEN($D30)=9,IF(OR(LEFT($D30,4)="111-",LEFT($D30,4)="119-"),"OK","NO"),"NA") | M30: =IF(B30="","",IF(L30="",B30,#REF!&"-"&B30)) | O30: =_xlfn.XLOOKUP($D30,'Cost Center'!$A:$A,'Cost Center'!$B:$B)
A31: 7 | L31: =IF(LEN($D31)=9,IF(OR(LEFT($D31,4)="111-",LEFT($D31,4)="119-"),"OK","NO"),"NA") | M31: =IF(B31="","",IF(L31="",B31,#REF!&"-"&B31)) | O31: =_xlfn.XLOOKUP($D31,'Cost Center'!$A:$A,'Cost Center'!$B:$B)
A32: 8 | L32: =IF(LEN($D32)=9,IF(OR(LEFT($D32,4)="111-",LEFT($D32,4)="119-"),"OK","NO"),"NA") | M32: =IF(B32="","",IF(L32="",B32,#REF!&"-"&B32)) | O32: =_xlfn.XLOOKUP($D32,'Cost Center'!$A:$A,'Cost Center'!$B:$B)
A33: 9 | L33: =IF(LEN($D33)=9,IF(OR(LEFT($D33,4)="111-",LEFT($D33,4)="119-"),"OK","NO"),"NA") | M33: =IF(B33="","",IF(L33="",B33,#REF!&"-"&B33)) | O33: =_xlfn.XLOOKUP($D33,'Cost Center'!$A:$A,'Cost Center'!$B:$B)
A34: 10 | L34: =IF(LEN($D34)=9,IF(OR(LEFT($D34,4)="111-",LEFT($D34,4)="119-"),"OK","NO"),"NA") | M34: =IF(B34="","",IF(L34="",B34,#REF!&"-"&B34)) | O34: =_xlfn.XLOOKUP($D34,'Cost Center'!$A:$A,'Cost Center'!$B:$B)
A35: 11 | L35: =IF(LEN($D35)=9,IF(OR(LEFT($D35,4)="111-",LEFT($D35,4)="119-"),"OK","NO"),"NA") | M35: =IF(B35="","",IF(L35="",B35,#REF!&"-"&B35)) | O35: =_xlfn.XLOOKUP($D35,'Cost Center'!$A:$A,'Cost Center'!$B:$B)
A36: 12 | L36: =IF(LEN($D36)=9,IF(OR(LEFT($D36,4)="111-",LEFT($D36,4)="119-"),"OK","NO"),"NA") | M36: =IF(B36="","",IF(L36="",B36,#REF!&"-"&B36)) | O36: =_xlfn.XLOOKUP($D36,'Cost Center'!$A:$A,'Cost Center'!$B:$B)
A37: 13 | L37: =IF(LEN($D37)=9,IF(OR(LEFT($D37,4)="111-",LEFT($D37,4)="119-"),"OK","NO"),"NA") | M37: =IF(B37="","",IF(L37="",B37,#REF!&"-"&B37)) | O37: =_xlfn.XLOOKUP($D37,'Cost Center'!$A:$A,'Cost Center'!$B:$B)
A38: 14 | L38: =IF(LEN($D38)=9,IF(OR(LEFT($D38,4)="111-",LEFT($D38,4)="119-"),"OK","NO"),"NA") | M38: =IF(B38="","",IF(L38="",B38,#REF!&"-"&B38)) | O38: =_xlfn.XLOOKUP($D38,'Cost Center'!$A:$A,'Cost Center'!$B:$B)
... A54: 30 | L54: =IF(LEN($D54)=9,IF(OR(LEFT($D54,4)="111-",LEFT($D54,4)="119-"),"OK","NO"),"NA") | M54: =IF(B54="","",IF(L54="",B54,#REF!&"-"&B54)) | O54: =_xlfn.XLOOKUP($D54,'Cost Center'!$A:$A,'Cost Center'!$B:$B)
E55: Net Amount(Without VAT): 不含税金额:
E56: Tax Amount: 税额：
E57: Gross Amount(With VAT): 含税总金额: | G57: =SUM(G55:G56)
E58: Tax Rate: 税率:
...

Sheet 标准邮件发送样式

Sheet Internal Order
A1: Internal order | B1: Internal order | C1: Person responsible
A2: 300600000001 | B2: TRAINING-PRODUCT TRAINING | C2: SSOONG1
A3: 300600000002 | B3: TRAINING-COLLECTION TRAINING | C3: SSOONG1
A4: 300600000003 | B4: TRAINING-OTHERS | C4: SSOONG1
A5: 300600000004 | B5: CRM-SPRING PREVIEW | C5: SSOONG1
A6: 300600000005 | B6: TRAINING-ONBOARDING TRAINING | C6: SSOONG1
A7: 300600000006 | B7: TRAINING-LEADERSHIP PROGRAM | C7: SSOONG1
A8: 300600000007 | B8: TRAINING-TALENT WORKSHOP | C8: SSOONG1
A9: 300600000008 | B9: TRAINING-TRAINING TOOLS | C9: SSOONG1
A10: 300600000009 | B10: CRM-CAPSULE COLLAB LAUNCHES | C10: SSOONG1
A11: 300600000010 | B11: GA-GS-ANNUAL/XMAS DINNER | C11: DLI13
A12: 300600000012 | B12: GA-HR-EXTERNAL TRAINING | C12: DLI13
... A61: 300600000093 | B61: WH-STORE DELIVERY&WAREHOUSE OPERATION RE | C61: CLIN24

Sheet WBS
A1: Project | C1: Project Profile | E1: Creation date | F1: Creation user name | G1: WBS element | I1: Invest. profile | K1: Approver
A2: P-COM-3006-18-25200 | B2: Advertising | C2: COM | D2: Communication | E2: 21.12.2025 | F2: WYAP | G2: W-COM-3006-18-25200-100 | H2: Advertising - Print | I2: # | J2: Not assigned | K2: ASUN7
A3: P-COM-3006-18-25200 | B3: Advertising | C3: COM | D3: Communication | E3: 21.12.2025 | F3: WYAP | G3: W-COM-3006-18-25200-200 | H3: Advertising - Outdoor | I3: # | J3: Not assigned | K3: ASUN7
A4: P-COM-3006-18-25200 | B4: Advertising | C4: COM | D4: Communication | E4: 21.12.2025 | F4: WYAP | G4: W-COM-3006-18-25200-300 | H4: Advertising - Digital | I4: # | J4: Not assigned | K4: ASUN7
A5: P-COM-3006-18-25200 | B5: Advertising | C5: COM | D5: Communication | E5: 21.12.2025 | F5: WYAP | G5: W-COM-3006-18-25200-400 | H5: Advertising - Search | I5: # | J5: Not assigned | K5: ASUN7
A6: P-COM-3006-18-25200 | B6: Advertising | C6: COM | D6: Communication | E6: 21.12.2025 | F6: WYAP | G6: W-COM-3006-18-25200-500 | H6: Advertising - Retainers | I6: # | J6: Not assigned | K6: ASUN7
A7: P-INV-3006-18-11000 | B7: CN-GUANGZHOU TAIKOO HUI-EXPANSION | C7: Z000006 | D7: Leasehold Improvement AUC - Store | E7: 21.12.2025 | F7: WYAP | G7: W-INV-3006-18-11000-141 | H7: CN-GUANGZHOU TAIKOO HUI-EXPANSION | I7: Z00006 | J7: Leasehold improvement AUC - Store | K7: JSHIN9
A8: P-INV-3006-18-11000 | B8: CN-GUANGZHOU TAIKOO HUI-EXPANSION | C8: Z000006 | D8: Leasehold Improvement AUC - Store | E8: 21.12.2025 | F8: WYAP | G8: W-INV-3006-18-11000-142 | H8: CN-GUANGZHOU TAIKOO HUI-EXPANSION | I8: Z00006 | J8: Leasehold improvement AUC - Store | K8: JSHIN9
A9: P-INV-3006-18-11000 | B9: CN-GUANGZHOU TAIKOO HUI-EXPANSION | C9: Z000006 | D9: Leasehold Improvement AUC - Store | E9: 21.12.2025 | F9: WYAP | G9: W-INV-3006-18-11000-143 | H9: CN-GUANGZHOU TAIKOO HUI-EXPANSION | I9: Z00006 | J9: Leasehold improvement AUC - Store | K9: JSHIN9
A10: P-INV-3006-18-11000 | B10: CN-GUANGZHOU TAIKOO HUI-EXPANSION | C10: Z000006 | D10: Leasehold Improvement AUC - Store | E10: 21.12.2025 | F10: WYAP | G10: W-INV-3006-18-11000-144 | H10: CN-GUANGZHOU TAIKOO HUI-EXPANSION | I10: Z00006 | J10: Leasehold improvement AUC - Store | K10: JSHIN9
A11: P-INV-3006-18-11000 | B11: CN-GUANGZHOU TAIKOO HUI-EXPANSION | C11: Z000006 | D11: Leasehold Improvement AUC - Store | E11: 21.12.2025 | F11: WYAP | G11: W-INV-3006-18-11000-145 | H11: CN-GUANGZHOU TAIKOO HUI-EXPANSION | I11: Z00006 | J11: Leasehold improvement AUC - Store | K11: JSHIN9
A12: P-INV-3006-18-11000 | B12: CN-GUANGZHOU TAIKOO HUI-EXPANSION | C12: Z000006 | D12: Leasehold Improvement AUC - Store | E12: 21.12.2025 | F12: WYAP | G12: W-INV-3006-18-11000-146 | H12: CN-GUANGZHOU TAIKOO HUI-EXPANSION | I12: Z00006 | J12: Leasehold improvement AUC - Store | K12: JSHIN9
A13: P-INV-3006-18-11000 | B13: CN-GUANGZHOU TAIKOO HUI-EXPANSION | C13: Z000006 | D13: Leasehold Improvement AUC - Store | E13: 21.12.2025 | F13: WYAP | G13: W-INV-3006-18-11000-147 | H13: CN-GUANGZHOU TAIKOO HUI-EXPANSION | I13: Z00006 | J13: Leasehold improvement AUC - Store | K13: JSHIN9
... A38: P-OTH-3006-18-25600 | B38: Fashion show | C38: CRM | D38: CRM Projects | E38: 21.12.2025 | F38: WYAP | G38: W-OTH-3006-18-25600-202 | H38: VIC PREVIEW - SPRING / SUMMER | I38: # | J38: Not assigned | K38: SSOONG1

Sheet Cost Center
A1: Cost center | B1: Cost center | C1: Functional area | D1: Functional area | E1: Department | F1: Cost center category | G1: User resp. | H1: Name 1 | I1: District
A2: 3006181010 | B2: CN-BA-PEK-BJCW | C2: CC1200 | D2: Store Exp | E2: BALBEJ2 | F2: Retail | G2: IDONG | H2: 巴黎世家贸易(上海)有限公司北京国贸分公司 | I2: 82107
A3: 3006181014 | B3: CN-BA-PEK-BJGLF | C3: CC1200 | D3: Store Exp | E3: BALCNP9 | F3: Retail | G3: IDONG | H3: # | I3: 82118
A4: 3006181016 | B4: CN-BA-PEK-BJSLT | C4: CC1200 | D4: Store Exp | E4: BALBEJ | F4: Retail | G4: IDONG | H4: 巴黎世家贸易（上海）有限公司北京分公司 | I4: 82105
A5: 3006181018 | B5: CN-BA-PEK-BJSKP 2F | C5: CC1200 | D5: Store Exp | E5: BALCNP28 | F5: Retail | G5: IDONG | H5: # | I5: 82143
A6: 3006181024 | B6: CN-BA-PEK-BJSKP 1F | C6: CC1200 | D6: Store Exp | E6: BALCNP27 | F6: Retail | G6: IDONG | H6: # | I6: 82136
A7: 3006181026 | B7: CN-BA-PEK-BJSKP 4F | C7: CC1200 | D7: Store Exp | E7: BALCNP29 | F7: Retail | G7: IDONG | H7: # | I7: 82137
A8: 3006181028 | B8: CN-BA-PEK-BJSKP S | C8: CC1200 | D8: Store Exp | E8: BALCNP39 | F8: Retail | G8: IDONG | H8: # | I8: 82146
A9: 3006181030 | B9: CN-BA-CHS-CSIFS | C9: CC1200 | D9: Store Exp | E9: BALCNP19 | F9: Retail | G9: IDONG | H9: 巴黎世家贸易(上海)有限公司长沙第一分公司 | I9: 82133
A10: 3006181032 | B10: CN-BA-CHE-CDFV | C10: CC1200 | D10: Store Exp | E10: BALCNP47 | F10: Retail | G10: IDONG | H10: 巴黎世家贸易（上海）有限公司成都第二分公司 | I10: 82149
A11: 3006181034 | B11: CN-BA-CHE-CDIFS | C11: CC1200 | D11: Store Exp | E11: BALCNP7 | F11: Retail | G11: IDONG | H11: 巴黎世家贸易(上海)有限公司成都国际金融中心分公司 | I11: 82119
A12: 3006181036 | B12: CN-BA-CHE-CDYT | C12: CC1200 | D12: Store Exp | E12: BALCNP42 | F12: Retail | G12: IDONG | H12: 巴黎世家贸易（上海）有限公司成都第一分公司 | I12: 82148
... A101: 3006181302 | B101: CN-BA-SO-CRM | C101: CC1453 | D101: Store Operations | E101: # | F101: Retail | G101: SSOONG1 | H101: # | I101: #

Sheet Sheet2
A1: CNY
A2: HKD
A3: CHF
A4: EUR
A5: USD
A6: GBP
A7: TWD
A8: MOP
A9: SGD
A10: JPY
A11: AUD
A12: KRW

Sheet Sheet1
A1: Company Name
A2: Richemont Commercial Co., Ltd.
A3: Shanghai Richemont Twin Villas Commercial and Trading Co., Ltd.
A4: Richemont Trading (Shanghai) Co., Ltd.
A5: Richemont (Beijing) Commercial and Trading Co., Ltd.
A6: Shenyang Richemont Vendome Commercial and Trading Co., Ltd.
A7: Hangzhou Richemont Commercial and Trading Co., Ltd.
A8: Richemont Commercial Guangzhou Co., Ltd.
A9: Chengdu Richemont Vendome Commercial and Trading Co., Ltd.
A10: Montblanc Commercial (China) Company Limited
A11: Alfred Dunhill (Shanghai) Trading Company Limited
